<mujoco model="H3_Squeeze">

  <asset>
    <mesh name="i11_horizontal_base" file="i11_horizontal_base.stl" scale="1 1 1"/>
    <mesh name="i11_traj_convex_part_0" file="i11_traj_decomposed_meshes/i11_traj_convex_part_0.obj" scale="1 1 1"/>
    <mesh name="i11_traj_convex_part_1" file="i11_traj_decomposed_meshes/i11_traj_convex_part_1.obj" scale="1 1 1"/>
    <mesh name="i11_traj_convex_part_2" file="i11_traj_decomposed_meshes/i11_traj_convex_part_2.obj" scale="1 1 1"/>
    <mesh name="i11_traj_convex_part_3" file="i11_traj_decomposed_meshes/i11_traj_convex_part_3.obj" scale="1 1 1"/>
    <mesh name="i11_traj_convex_part_4" file="i11_traj_decomposed_meshes/i11_traj_convex_part_4.obj" scale="1 1 1"/>
    <mesh name="i11_traj_convex_part_5" file="i11_traj_decomposed_meshes/i11_traj_convex_part_5.obj" scale="1 1 1"/>
    <mesh name="i11_traj_convex_part_6" file="i11_traj_decomposed_meshes/i11_traj_convex_part_6.obj" scale="1 1 1"/>
    <mesh name="i11_traj_convex_part_7" file="i11_traj_decomposed_meshes/i11_traj_convex_part_7.obj" scale="1 1 1"/>
    <mesh name="i11_traj_convex_part_8" file="i11_traj_decomposed_meshes/i11_traj_convex_part_8.obj" scale="1 1 1"/>
    <mesh name="i11_traj_convex_part_9" file="i11_traj_decomposed_meshes/i11_traj_convex_part_9.obj" scale="1 1 1"/>
    <mesh name="i11_traj_convex_part_10" file="i11_traj_decomposed_meshes/i11_traj_convex_part_10.obj" scale="1 1 1"/>
    <mesh name="i11_traj_convex_part_11" file="i11_traj_decomposed_meshes/i11_traj_convex_part_11.obj" scale="1 1 1"/>
    <mesh name="i11_traj_convex_part_12" file="i11_traj_decomposed_meshes/i11_traj_convex_part_12.obj" scale="1 1 1"/>
    <mesh name="i11_traj_convex_part_13" file="i11_traj_decomposed_meshes/i11_traj_convex_part_13.obj" scale="1 1 1"/>
    <mesh name="i11_traj_convex_part_14" file="i11_traj_decomposed_meshes/i11_traj_convex_part_14.obj" scale="1 1 1"/>
    <mesh name="i11_traj_convex_part_15" file="i11_traj_decomposed_meshes/i11_traj_convex_part_15.obj" scale="1 1 1"/>
    <mesh name="i11_traj_convex_part_16" file="i11_traj_decomposed_meshes/i11_traj_convex_part_16.obj" scale="1 1 1"/>
    <mesh name="i11_traj_convex_part_17" file="i11_traj_decomposed_meshes/i11_traj_convex_part_17.obj" scale="1 1 1"/>
    <mesh name="i11_traj_convex_part_18" file="i11_traj_decomposed_meshes/i11_traj_convex_part_18.obj" scale="1 1 1"/>

    <mesh name="syringe_barrier" file="syringe_barrier.stl" scale="1 1 1"/>
    <mesh name="syringe_rod" file="syringe_rod.stl" scale="1 1 1"/>

    <mesh name="i11_ring_convex_part_0" file="i11_ring_decomposed_meshes/i11_ring_convex_part_0.obj" scale="1 1 1"/>
    <mesh name="i11_ring_convex_part_1" file="i11_ring_decomposed_meshes/i11_ring_convex_part_1.obj" scale="1 1 1"/>
    <mesh name="i11_ring_convex_part_2" file="i11_ring_decomposed_meshes/i11_ring_convex_part_2.obj" scale="1 1 1"/>
    <mesh name="i11_ring_convex_part_3" file="i11_ring_decomposed_meshes/i11_ring_convex_part_3.obj" scale="1 1 1"/>
    <mesh name="i11_ring_convex_part_4" file="i11_ring_decomposed_meshes/i11_ring_convex_part_4.obj" scale="1 1 1"/>
    <mesh name="i11_ring_convex_part_5" file="i11_ring_decomposed_meshes/i11_ring_convex_part_5.obj" scale="1 1 1"/>
    <mesh name="i11_ring_convex_part_6" file="i11_ring_decomposed_meshes/i11_ring_convex_part_6.obj" scale="1 1 1"/>
    <mesh name="i11_ring_convex_part_7" file="i11_ring_decomposed_meshes/i11_ring_convex_part_7.obj" scale="1 1 1"/>
    <mesh name="i11_ring_convex_part_8" file="i11_ring_decomposed_meshes/i11_ring_convex_part_8.obj" scale="1 1 1"/>
    <mesh name="i11_ring_convex_part_9" file="i11_ring_decomposed_meshes/i11_ring_convex_part_9.obj" scale="1 1 1"/>
    <mesh name="i11_ring_convex_part_10" file="i11_ring_decomposed_meshes/i11_ring_convex_part_10.obj" scale="1 1 1"/>
    <mesh name="i11_ring_convex_part_11" file="i11_ring_decomposed_meshes/i11_ring_convex_part_11.obj" scale="1 1 1"/>
    <mesh name="i11_ring_convex_part_12" file="i11_ring_decomposed_meshes/i11_ring_convex_part_12.obj" scale="1 1 1"/>
    <mesh name="i11_ring_convex_part_13" file="i11_ring_decomposed_meshes/i11_ring_convex_part_13.obj" scale="1 1 1"/>
    <mesh name="i11_ring_convex_part_14" file="i11_ring_decomposed_meshes/i11_ring_convex_part_14.obj" scale="1 1 1"/>
    <mesh name="i11_ring_convex_part_15" file="i11_ring_decomposed_meshes/i11_ring_convex_part_15.obj" scale="1 1 1"/>
    <mesh name="i11_ring_convex_part_16" file="i11_ring_decomposed_meshes/i11_ring_convex_part_16.obj" scale="1 1 1"/>
    <mesh name="i11_ring_convex_part_17" file="i11_ring_decomposed_meshes/i11_ring_convex_part_17.obj" scale="1 1 1"/>
    <mesh name="i11_ring_convex_part_18" file="i11_ring_decomposed_meshes/i11_ring_convex_part_18.obj" scale="1 1 1"/>
    <mesh name="i11_ring_convex_part_19" file="i11_ring_decomposed_meshes/i11_ring_convex_part_19.obj" scale="1 1 1"/>
    <mesh name="i11_ring_convex_part_20" file="i11_ring_decomposed_meshes/i11_ring_convex_part_20.obj" scale="1 1 1"/>
    <mesh name="i11_ring_convex_part_21" file="i11_ring_decomposed_meshes/i11_ring_convex_part_21.obj" scale="1 1 1"/>
    <mesh name="i11_ring_convex_part_22" file="i11_ring_decomposed_meshes/i11_ring_convex_part_22.obj" scale="1 1 1"/>
    <mesh name="i11_ring_convex_part_23" file="i11_ring_decomposed_meshes/i11_ring_convex_part_23.obj" scale="1 1 1"/>
    <mesh name="i11_ring_convex_part_24" file="i11_ring_decomposed_meshes/i11_ring_convex_part_24.obj" scale="1 1 1"/>
    <mesh name="i11_ring_convex_part_25" file="i11_ring_decomposed_meshes/i11_ring_convex_part_25.obj" scale="1 1 1"/>
    <mesh name="i11_ring_convex_part_26" file="i11_ring_decomposed_meshes/i11_ring_convex_part_26.obj" scale="1 1 1"/>
    <mesh name="i11_ring_convex_part_27" file="i11_ring_decomposed_meshes/i11_ring_convex_part_27.obj" scale="1 1 1"/>
    <mesh name="i11_ring_convex_part_28" file="i11_ring_decomposed_meshes/i11_ring_convex_part_28.obj" scale="1 1 1"/>
    <mesh name="i11_ring_convex_part_29" file="i11_ring_decomposed_meshes/i11_ring_convex_part_29.obj" scale="1 1 1"/>
    <mesh name="i11_ring_convex_part_30" file="i11_ring_decomposed_meshes/i11_ring_convex_part_30.obj" scale="1 1 1"/>
    <mesh name="i11_ring_convex_part_31" file="i11_ring_decomposed_meshes/i11_ring_convex_part_31.obj" scale="1 1 1"/>
    <mesh name="i11_ring_convex_part_32" file="i11_ring_decomposed_meshes/i11_ring_convex_part_32.obj" scale="1 1 1"/>
    <mesh name="i11_ring_convex_part_33" file="i11_ring_decomposed_meshes/i11_ring_convex_part_33.obj" scale="1 1 1"/>
    <mesh name="i11_ring_convex_part_34" file="i11_ring_decomposed_meshes/i11_ring_convex_part_34.obj" scale="1 1 1"/>

    <material name="object_material" rgba="1 1 1 1" shininess="0.3"/>
  </asset>

  <default>
    <default class="visual">
      <geom contype="0" conaffinity="0" group="2"/>
    </default>
    <default class="collision">
      <geom group="3"/>
    </default>
  </default>

  <worldbody>
    <body name="i11_horizontal_base_body" pos="0 0 0.2">
      <geom name="i11_horizontal_base" type="mesh" mesh="i11_horizontal_base" material="object_material" mass="1" class="visual"/>
      <geom type="box" size="0.003 0.020 0.0775" pos="-0.1155 -0.0118 0.0775" density="248" class="collision"/>
      <geom type="box" size="0.003 0.020 0.0775" pos="0.1155 -0.0118 0.0775" density="248" class="collision"/>
      <geom name="i11_traj_convex_part_0" type="mesh" mesh="i11_traj_convex_part_0" class="collision" solref="0.002 1" friction="3 0.1 0.1"/>
      <geom name="i11_traj_convex_part_1" type="mesh" mesh="i11_traj_convex_part_1" class="collision" solref="0.002 1" friction="3 0.1 0.1"/>
      <geom name="i11_traj_convex_part_2" type="mesh" mesh="i11_traj_convex_part_2" class="collision" solref="0.002 1" friction="3 0.1 0.1"/>
      <geom name="i11_traj_convex_part_3" type="mesh" mesh="i11_traj_convex_part_3" class="collision" solref="0.002 1" friction="3 0.1 0.1"/>
      <geom name="i11_traj_convex_part_4" type="mesh" mesh="i11_traj_convex_part_4" class="collision" solref="0.002 1" friction="3 0.1 0.1"/>
      <geom name="i11_traj_convex_part_5" type="mesh" mesh="i11_traj_convex_part_5" class="collision" solref="0.002 1" friction="3 0.1 0.1"/>
      <geom name="i11_traj_convex_part_6" type="mesh" mesh="i11_traj_convex_part_6" class="collision" solref="0.002 1" friction="3 0.1 0.1"/>
      <geom name="i11_traj_convex_part_7" type="mesh" mesh="i11_traj_convex_part_7" class="collision" solref="0.002 1" friction="3 0.1 0.1"/>
      <geom name="i11_traj_convex_part_8" type="mesh" mesh="i11_traj_convex_part_8" class="collision" solref="0.002 1" friction="3 0.1 0.1"/>
      <geom name="i11_traj_convex_part_9" type="mesh" mesh="i11_traj_convex_part_9" class="collision" solref="0.002 1" friction="3 0.1 0.1"/>
      <geom name="i11_traj_convex_part_10" type="mesh" mesh="i11_traj_convex_part_10" class="collision" solref="0.002 1" friction="3 0.1 0.1"/>
      <geom name="i11_traj_convex_part_11" type="mesh" mesh="i11_traj_convex_part_11" class="collision" solref="0.002 1" friction="3 0.1 0.1"/>
      <geom name="i11_traj_convex_part_12" type="mesh" mesh="i11_traj_convex_part_12" class="collision" solref="0.002 1" friction="3 0.1 0.1"/>
      <geom name="i11_traj_convex_part_13" type="mesh" mesh="i11_traj_convex_part_13" class="collision" solref="0.002 1" friction="3 0.1 0.1"/>
      <geom name="i11_traj_convex_part_14" type="mesh" mesh="i11_traj_convex_part_14" class="collision" solref="0.002 1" friction="3 0.1 0.1"/>
      <geom name="i11_traj_convex_part_15" type="mesh" mesh="i11_traj_convex_part_15" class="collision" solref="0.002 1" friction="3 0.1 0.1"/>
      <geom name="i11_traj_convex_part_16" type="mesh" mesh="i11_traj_convex_part_16" class="collision" solref="0.002 1" friction="3 0.1 0.1"/>
      <geom name="i11_traj_convex_part_17" type="mesh" mesh="i11_traj_convex_part_17" class="collision" solref="0.002 1" friction="3 0.1 0.1"/>
      <geom name="i11_traj_convex_part_18" type="mesh" mesh="i11_traj_convex_part_18" class="collision" solref="0.002 1" friction="3 0.1 0.1"/>
    </body>

    <body name="syringe_body" pos="-0.1095 -0.0478 0.29">
      <joint name="syringe_slide" type="slide" axis="1 0 0" range="0 0.219" damping="0.05"/>
      <geom name="syringe_barrier" type="mesh" mesh="syringe_barrier" material="object_material" class="visual"/>
      <geom type="cylinder" size="0.0092 0.003" quat="0.7071068 0 0.7071068 0" pos="0 0.026 0.015" density="248" class="collision" solref="0.002 1"/>
      <geom type="cylinder" size="0.0115 0.015" pos="0 0 0.015" density="248" class="collision"/>
      <geom type="box" size="0.0315 0.0075 0.0025" pos="0 0 0.0025" density="248" class="collision"/>
      <body name="rod_body" pos="0 0 0">
        <joint name="rod_slide" type="slide" axis="0 0 1" range="0 0.045" damping="0.05"/>
        <geom name="syringe_rod" type="mesh" mesh="syringe_rod" material="object_material" class="visual"/>
        <geom type="cylinder" size="0.00625 0.0375" pos="0 0 -0.0075" density="248" class="collision"/>
        <geom type="cylinder" size="0.0115 0.002" pos="0 0 -0.047" density="248" class="collision"/>
        <geom name="i11_ring_convex_part_0" type="mesh" mesh="i11_ring_convex_part_0" pos="0 0 0.048" density="248" class="collision" friction="3 0.1 0.1"/>
        <geom name="i11_ring_convex_part_1" type="mesh" mesh="i11_ring_convex_part_1" pos="0 0 0.048" density="248" class="collision" friction="3 0.1 0.1"/>
        <geom name="i11_ring_convex_part_2" type="mesh" mesh="i11_ring_convex_part_2" pos="0 0 0.048" density="248" class="collision" friction="3 0.1 0.1"/>
        <geom name="i11_ring_convex_part_3" type="mesh" mesh="i11_ring_convex_part_3" pos="0 0 0.048" density="248" class="collision" friction="3 0.1 0.1"/>
        <geom name="i11_ring_convex_part_4" type="mesh" mesh="i11_ring_convex_part_4" pos="0 0 0.048" density="248" class="collision" friction="3 0.1 0.1"/>
        <geom name="i11_ring_convex_part_5" type="mesh" mesh="i11_ring_convex_part_5" pos="0 0 0.048" density="248" class="collision" friction="3 0.1 0.1"/>
        <geom name="i11_ring_convex_part_6" type="mesh" mesh="i11_ring_convex_part_6" pos="0 0 0.048" density="248" class="collision" friction="3 0.1 0.1"/>
        <geom name="i11_ring_convex_part_7" type="mesh" mesh="i11_ring_convex_part_7" pos="0 0 0.048" density="248" class="collision" friction="3 0.1 0.1"/>
        <geom name="i11_ring_convex_part_8" type="mesh" mesh="i11_ring_convex_part_8" pos="0 0 0.048" density="248" class="collision" friction="3 0.1 0.1"/>
        <geom name="i11_ring_convex_part_9" type="mesh" mesh="i11_ring_convex_part_9" pos="0 0 0.048" density="248" class="collision" friction="3 0.1 0.1"/>
        <geom name="i11_ring_convex_part_10" type="mesh" mesh="i11_ring_convex_part_10" pos="0 0 0.048" density="248" class="collision" friction="3 0.1 0.1"/>
        <geom name="i11_ring_convex_part_11" type="mesh" mesh="i11_ring_convex_part_11" pos="0 0 0.048" density="248" class="collision" friction="3 0.1 0.1"/>
        <geom name="i11_ring_convex_part_12" type="mesh" mesh="i11_ring_convex_part_12" pos="0 0 0.048" density="248" class="collision" friction="3 0.1 0.1"/>
        <geom name="i11_ring_convex_part_13" type="mesh" mesh="i11_ring_convex_part_13" pos="0 0 0.048" density="248" class="collision" friction="3 0.1 0.1"/>
        <geom name="i11_ring_convex_part_14" type="mesh" mesh="i11_ring_convex_part_14" pos="0 0 0.048" density="248" class="collision" friction="3 0.1 0.1"/>
        <geom name="i11_ring_convex_part_15" type="mesh" mesh="i11_ring_convex_part_15" pos="0 0 0.048" density="248" class="collision" friction="3 0.1 0.1"/>
        <geom name="i11_ring_convex_part_16" type="mesh" mesh="i11_ring_convex_part_16" pos="0 0 0.048" density="248" class="collision" friction="3 0.1 0.1"/>
        <geom name="i11_ring_convex_part_17" type="mesh" mesh="i11_ring_convex_part_17" pos="0 0 0.048" density="248" class="collision" friction="3 0.1 0.1"/>
        <geom name="i11_ring_convex_part_18" type="mesh" mesh="i11_ring_convex_part_18" pos="0 0 0.048" density="248" class="collision" friction="3 0.1 0.1"/>
        <geom name="i11_ring_convex_part_19" type="mesh" mesh="i11_ring_convex_part_19" pos="0 0 0.048" density="248" class="collision" friction="3 0.1 0.1"/>
        <geom name="i11_ring_convex_part_20" type="mesh" mesh="i11_ring_convex_part_20" pos="0 0 0.048" density="248" class="collision" friction="3 0.1 0.1"/>
        <geom name="i11_ring_convex_part_21" type="mesh" mesh="i11_ring_convex_part_21" pos="0 0 0.048" density="248" class="collision" friction="3 0.1 0.1"/>
        <geom name="i11_ring_convex_part_22" type="mesh" mesh="i11_ring_convex_part_22" pos="0 0 0.048" density="248" class="collision" friction="3 0.1 0.1"/>
        <geom name="i11_ring_convex_part_23" type="mesh" mesh="i11_ring_convex_part_23" pos="0 0 0.048" density="248" class="collision" friction="3 0.1 0.1"/>
        <geom name="i11_ring_convex_part_24" type="mesh" mesh="i11_ring_convex_part_24" pos="0 0 0.048" density="248" class="collision" friction="3 0.1 0.1"/>
        <geom name="i11_ring_convex_part_25" type="mesh" mesh="i11_ring_convex_part_25" pos="0 0 0.048" density="248" class="collision" friction="3 0.1 0.1"/>
        <geom name="i11_ring_convex_part_26" type="mesh" mesh="i11_ring_convex_part_26" pos="0 0 0.048" density="248" class="collision" friction="3 0.1 0.1"/>
        <geom name="i11_ring_convex_part_27" type="mesh" mesh="i11_ring_convex_part_27" pos="0 0 0.048" density="248" class="collision" friction="3 0.1 0.1"/>
        <geom name="i11_ring_convex_part_28" type="mesh" mesh="i11_ring_convex_part_28" pos="0 0 0.048" density="248" class="collision" friction="3 0.1 0.1"/>
        <geom name="i11_ring_convex_part_29" type="mesh" mesh="i11_ring_convex_part_29" pos="0 0 0.048" density="248" class="collision" friction="3 0.1 0.1"/>
        <geom name="i11_ring_convex_part_30" type="mesh" mesh="i11_ring_convex_part_30" pos="0 0 0.048" density="248" class="collision" friction="3 0.1 0.1"/>
        <geom name="i11_ring_convex_part_31" type="mesh" mesh="i11_ring_convex_part_31" pos="0 0 0.048" density="248" class="collision" friction="3 0.1 0.1"/>
        <geom name="i11_ring_convex_part_32" type="mesh" mesh="i11_ring_convex_part_32" pos="0 0 0.048" density="248" class="collision" friction="3 0.1 0.1"/>
        <geom name="i11_ring_convex_part_33" type="mesh" mesh="i11_ring_convex_part_33" pos="0 0 0.048" density="248" class="collision" friction="3 0.1 0.1"/>
        <geom name="i11_ring_convex_part_34" type="mesh" mesh="i11_ring_convex_part_34" pos="0 0 0.048" density="248" class="collision" friction="3 0.1 0.1"/>
      </body>

    </body>

    
    
  </worldbody>
</mujoco>