<mujoco model="V3_Sphere">

  <asset>
    <mesh name="vertical_base" file="vertical_base.stl" scale="1 1 1"/>
    <mesh name="vertical_rod" file="vertical_rod.stl" scale="1 1 1"/>

    <material name="object_material" rgba="1 1 1 1" shininess="0.3"/>
  </asset>

  <default>
    <default class="visual">
      <geom contype="0" conaffinity="0" group="2"/>
    </default>
    <default class="collision">
      <geom group="3"/>
    </default>
  </default>

  <worldbody>
    <body name="vertical_base" pos="0 0 0">
      <geom name="vertical_base" type="mesh" mesh="vertical_base" material="object_material" class="visual"/>
      <geom type="cylinder" size="0.014 0.121" pos="0 0.02985 0.121" density="248" class="collision"/>
      <!-- 15deg platform1: CCW, 20% PLA density -->
      <geom size="0.0026 0.00792 0.004" quat="0.9914449 0 0 0.1305262" pos="-0.00548 -0.00117 0.038" type="box" density="248" class="collision"/>
      <geom size="0.0026 0.00792 0.004" quat="0.9914449 0 0 0.1305262" pos="0.00534 0.00172 0.038" type="box" density="248" class="collision"/>
      <geom size="0.003 0.002 0.004" quat="0.9914449 0 0 0.1305262" pos="-0.00160 0.00599 0.038" type="box" density="248" class="collision"/>
      <!-- 15deg platform2: CW, 20% PLA density -->
      <geom size="0.0026 0.00792 0.004" quat="0.9914449 0 0 -0.1305262" pos="0.00548 -0.00117 0.070" type="box" density="248" class="collision"/>
      <geom size="0.0026 0.00792 0.004" quat="0.9914449 0 0 -0.1305262" pos="-0.00534 0.00172 0.070" type="box" density="248" class="collision"/>
      <geom size="0.003 0.002 0.004" quat="0.9914449 0 0 -0.1305262" pos="0.00160 0.00599 0.070" type="box" density="248" class="collision"/>
      <!-- 30deg platform1: CCW, 20% PLA density -->
      <geom size="0.0026 0.00792 0.004" quat="0.9659258 0 0 0.2588190" pos="-0.00499 -0.00255 0.102" type="box" density="248" class="collision"/>
      <geom size="0.0026 0.00792 0.004" quat="0.9659258 0 0 0.2588190" pos="0.00471 0.00305 0.102" type="box" density="248" class="collision"/>
      <geom size="0.003 0.002 0.004" quat="0.9659258 0 0 0.2588190" pos="-0.00310 0.00537 0.102" type="box" density="248" class="collision"/>
      <!-- 30deg platform2: CW, 20% PLA density -->
      <geom size="0.0026 0.00792 0.004" quat="0.9659258 0 0 -0.2588190" pos="0.00499 -0.00255 0.134" type="box" density="248" class="collision"/>
      <geom size="0.0026 0.00792 0.004" quat="0.9659258 0 0 -0.2588190" pos="-0.00471 0.00305 0.134" type="box" density="248" class="collision"/>
      <geom size="0.003 0.002 0.004" quat="0.9659258 0 0 -0.2588190" pos="0.00310 0.00537 0.134" type="box" density="248" class="collision"/>
      <!-- 45deg platform1: CCW, 20% PLA density -->
      <geom size="0.0026 0.00792 0.004" quat="0.9238795 0 0 0.3826834" pos="-0.00416 -0.00376 0.166" type="box" density="248" class="collision"/>
      <geom size="0.0026 0.00792 0.004" quat="0.9238795 0 0 0.3826834" pos="0.00376 0.00416 0.166" type="box" density="248" class="collision"/>
      <geom size="0.003 0.002 0.004" quat="0.9238795 0 0 0.3826834" pos="-0.00438 0.00438 0.166" type="box" density="248" class="collision"/>
      <!-- 45deg platform2: CW, 20% PLA density -->
      <geom size="0.0026 0.00792 0.004" quat="0.9238795 0 0 -0.3826834" pos="0.00416 -0.00376 0.198" type="box" density="248" class="collision"/>
      <geom size="0.0026 0.00792 0.004" quat="0.9238795 0 0 -0.3826834" pos="-0.00376 0.00416 0.198" type="box" density="248" class="collision"/>
      <geom size="0.003 0.002 0.004" quat="0.9238795 0 0 -0.3826834" pos="0.00438 0.00438 0.198" type="box" density="248" class="collision"/>
      <!-- Top platform: 20% PLA density -->
      <geom size="0.0032 0.00999 0.004"  pos="0.0062 0.00087 0.228" type="box" density="248" class="collision"/>
      <geom size="0.0032 0.00999 0.004"  pos="-0.0062 0.00087 0.228" type="box" density="248" class="collision"/>
      <geom size="0.003 0.00335 0.004"  pos="0 0.0075 0.228" type="box" density="248" class="collision"/>
    </body>

    <body name="pen_rod" pos="0 0 0.233"> 
      <joint name="disk_rod_slide_joint" type="slide" pos="0 0 0" axis="0 0 1" range="-0.01 1" damping="100"/>
      <joint name="disk_rod_hinge_joint" type="hinge" axis="0 0 1"/>
      <geom type="sphere" size="0.0275" pos="0 0 0.06053" material="object_material" mass="0.05"/>
      <geom type="cylinder" size="0.003 0.030265" pos="0 0 0.030265" material="object_material" density="248"/>
      <geom type="cylinder" size="0.00625 0.010625" pos="0 0 0.010625" material="object_material" density="248"/>
      <geom type="cylinder" size="0.004 0.114375" pos="0 0 -0.114375" material="object_material" mass="0.05" class="visual"/>
      <geom type="box" size="0.002 0.005 0.004" pos="0 -0.005 -0.22475" material="object_material" density="248"/>
    </body>
    
  </worldbody>
</mujoco>