<?xml version="1.0" ?>
<robot name="orcahand">
   <link name="world">
      <inertial>
         <origin xyz="0.0 0.0 0.0" rpy="0.0 0.0 0.0"/>
         <mass value="0.0"/>
         <inertia ixx="0.0" iyy="0.0" izz="0.0" ixy="0" ixz="0" iyz="0"/>
      </inertial>
   </link>
   <link name="root">
      <inertial>
         <origin xyz="0.0 0.0 0.0" rpy="0.0 0.0 0.0"/>
         <mass value="0.0"/>
         <inertia ixx="0.0" iyy="0.0" izz="0.0" ixy="0" ixz="0" iyz="0"/>
      </inertial>
   </link>
   <link name="world2root_fixed_jointbody">
      <inertial>
         <origin xyz="0.0 0.0 0.0" rpy="0.0 0.0 0.0"/>
         <mass value="0.001"/>
         <inertia ixx="1e-09" iyy="1e-09" izz="1e-09" ixy="0" ixz="0" iyz="0"/>
      </inertial>
   </link>
   <joint type="fixed" name="world2root_fixed">
      <parent link="world"/>
      <child link="world2root_fixed_jointbody"/>
      <origin xyz="0.0 0.0 0.0" rpy="0.0 0.0 0.0"/>
   </joint>
   <joint type="fixed" name="world2root_fixed_offset">
      <parent link="world2root_fixed_jointbody"/>
      <child link="root"/>
      <origin xyz="-0.0 -0.0 -0.0" rpy="0.0 0.0 0.0"/>
   </joint>
   <link name="tower">
      <inertial>
         <origin xyz="0.040332210450118706 0.002125801351270809 0.01968127925815741" rpy="0.03116389785565374 0.006594058324928431 0.05135791026908916"/>
         <mass value="3.914536228486332"/>
         <inertia ixx="0.006344807113813945" iyy="0.005501052442445608" izz="0.0032062353988468895" ixy="0" ixz="0" iyz="0"/>
      </inertial>
      <visual name="tower_mesh">
         <origin xyz="0.040332210450118706 0.002125801351270809 0.01968127925815741" rpy="0.03116389785565373 0.006594058324928431 0.05135791026908915"/>
         <geometry>
            <mesh filename="assets/tower.stl"/>
         </geometry>
         <material name="white"/>
      </visual>
   </link>
   <link name="root2tower_fixed_jointbody">
      <inertial>
         <origin xyz="0.0 0.0 0.0" rpy="0.0 0.0 0.0"/>
         <mass value="0.001"/>
         <inertia ixx="1e-09" iyy="1e-09" izz="1e-09" ixy="0" ixz="0" iyz="0"/>
      </inertial>
   </link>
   <joint type="fixed" name="root2tower_fixed">
      <parent link="root"/>
      <child link="root2tower_fixed_jointbody"/>
      <origin xyz="0.0 0.0 0.0" rpy="0.0 0.0 0.0"/>
   </joint>
   <joint type="fixed" name="root2tower_fixed_offset">
      <parent link="root2tower_fixed_jointbody"/>
      <child link="tower"/>
      <origin xyz="-0.0 -0.0 -0.0" rpy="0.0 0.0 0.0"/>
   </joint>
   <link name="palm">
      <inertial>
         <origin xyz="0.0011316298941525988 -0.0006809529842112307 -0.006925098522788782" rpy="1.6605120710165795 0.04571983987140049 1.553804205661859"/>
         <mass value="0.21897280147188336"/>
         <inertia ixx="0.000133814767748963" iyy="9.472176530953664e-05" izz="5.683540838790515e-05" ixy="0" ixz="0" iyz="0"/>
      </inertial>
      <visual name="palm_mesh">
         <origin xyz="0.0011316298941525988 -0.0006809529842112307 -0.006925098522788782" rpy="1.6605120710165795 0.045719839871400714 1.553804205661859"/>
         <geometry>
            <mesh filename="assets/palm.stl"/>
         </geometry>
         <material name="white"/>
      </visual>
   </link>
   <link name="joint_palm_jointbody">
      <inertial>
         <origin xyz="0.0 0.0 0.0" rpy="0.0 0.0 0.0"/>
         <mass value="0.001"/>
         <inertia ixx="1e-09" iyy="1e-09" izz="1e-09" ixy="0" ixz="0" iyz="0"/>
      </inertial>
   </link>
   <joint type="revolute" name="joint_palm">
      <parent link="tower"/>
      <child link="joint_palm_jointbody"/>
      <origin xyz="0.040628908450627305 -1.3010426069826053e-18 0.10487107458169508" rpy="1.1102230246251556e-16 -8.881784197001252e-16 1.720153087273393e-17"/>
      <axis xyz="1.0000000000000009 1.7708749843666826e-16 -6.445457829160986e-17"/>
      <limit lower="-0.5235987755982988" upper="1.0471975511965976" effort="100" velocity="100"/>
   </joint>
   <joint type="fixed" name="joint_palm_offset">
      <parent link="joint_palm_jointbody"/>
      <child link="palm"/>
      <origin xyz="-0.0019999999999999844 0.0014412498723577962 0.038719313535195574" rpy="0.0 0.0 0.0"/>
   </joint>
   <link name="thumb_mp">
      <inertial>
         <origin xyz="0.0024248633410332435 2.8794542011742426e-09 0.003958821811995086" rpy="1.565685932226782e-06 0.018204092598166133 0.0"/>
         <mass value="0.01120025618913875"/>
         <inertia ixx="1.605701105355141e-06" iyy="1.2534125734613104e-06" izz="5.184363592598028e-07" ixy="0" ixz="0" iyz="0"/>
      </inertial>
      <visual name="thumb_mp_mesh">
         <origin xyz="0.0024248633410332435 2.8794542011742426e-09 0.003958821811995086" rpy="1.565685932226782e-06 0.018204092598166133 0.0"/>
         <geometry>
            <mesh filename="assets/thumb_mp.stl"/>
         </geometry>
         <material name="white"/>
      </visual>
   </link>
   <link name="joint_abd_thumb_jointbody">
      <inertial>
         <origin xyz="0.0 0.0 0.0" rpy="0.0 0.0 0.0"/>
         <mass value="0.001"/>
         <inertia ixx="1e-09" iyy="1e-09" izz="1e-09" ixy="0" ixz="0" iyz="0"/>
      </inertial>
   </link>
   <joint type="revolute" name="joint_abd_thumb">
      <parent link="palm"/>
      <child link="joint_abd_thumb_jointbody"/>
      <origin xyz="-0.028209038238965978 0.01777053753934476 -0.013209503444777428" rpy="0.5385748168211226 -0.05594923693864806 -1.2704659007702708"/>
      <axis xyz="0.0 0.0 -1.0"/>
      <limit lower="-0.9599310885968813" upper="0.7853981633974483" effort="100" velocity="100"/>
   </joint>
   <joint type="fixed" name="joint_abd_thumb_offset">
      <parent link="joint_abd_thumb_jointbody"/>
      <child link="thumb_mp"/>
      <origin xyz="-0.0 -0.0 -0.0" rpy="0.0 0.0 0.0"/>
   </joint>
   <link name="thumb_pp">
      <inertial>
         <origin xyz="0.017372399209090183 -3.728576908453657e-05 -0.0001642386811402271" rpy="-1.5208221659215448 -0.8100191809518881 -1.60266280027074"/>
         <mass value="0.017778981867848216"/>
         <inertia ixx="1.6000536227123918e-06" iyy="1.4843375050603895e-06" izz="1.05703234127632e-06" ixy="0" ixz="0" iyz="0"/>
      </inertial>
      <visual name="thumb_pp_mesh">
         <origin xyz="0.017372399209090183 -3.728576908453657e-05 -0.0001642386811402271" rpy="-1.5208221659215444 -0.8100191809518881 -1.6026628002707408"/>
         <geometry>
            <mesh filename="assets/thumb_pp.stl"/>
         </geometry>
         <material name="white"/>
      </visual>
   </link>
   <link name="joint_pip_thumb_jointbody">
      <inertial>
         <origin xyz="0.0 0.0 0.0" rpy="0.0 0.0 0.0"/>
         <mass value="0.001"/>
         <inertia ixx="1e-09" iyy="1e-09" izz="1e-09" ixy="0" ixz="0" iyz="0"/>
      </inertial>
   </link>
   <joint type="revolute" name="joint_pip_thumb">
      <parent link="thumb_mp"/>
      <child link="joint_pip_thumb_jointbody"/>
      <origin xyz="-4.5102810375396984e-17 1.5563939026463913e-16 4.687222832089333e-17" rpy="-1.221730476396032 -4.440892098500626e-16 -9.992007221626409e-16"/>
      <axis xyz="0.0 0.34222508701641263 0.9396180020713785"/>
      <limit lower="-0.3490658503988659" upper="0.7330382858376184" effort="100" velocity="100"/>
   </joint>
   <joint type="fixed" name="joint_pip_thumb_offset">
      <parent link="joint_pip_thumb_jointbody"/>
      <child link="thumb_pp"/>
      <origin xyz="-0.03 -0.0 -0.0" rpy="0.0 0.0 0.0"/>
   </joint>
   <link name="thumb_ip">
      <inertial>
         <origin xyz="0.0014193666210186085 8.673552400660678e-06 0.013611608297713454" rpy="-0.0006651622688937844 0.02470989391442102 0.0013108316876743052"/>
         <mass value="0.015525372290662061"/>
         <inertia ixx="1.849733004237475e-06" iyy="1.7750616046334623e-06" izz="6.56720600070246e-07" ixy="0" ixz="0" iyz="0"/>
      </inertial>
      <visual name="thumb_ip_mesh">
         <origin xyz="0.0014193666210186085 8.673552400660678e-06 0.013611608297713454" rpy="-0.0006651622688937844 0.02470989391442102 0.0013108316876743052"/>
         <geometry>
            <mesh filename="assets/thumb_ip.stl"/>
         </geometry>
         <material name="white"/>
      </visual>
   </link>
   <link name="joint_iip_thumb_jointbody">
      <inertial>
         <origin xyz="0.0 0.0 0.0" rpy="0.0 0.0 0.0"/>
         <mass value="0.001"/>
         <inertia ixx="1e-09" iyy="1e-09" izz="1e-09" ixy="0" ixz="0" iyz="0"/>
      </inertial>
   </link>
   <joint type="revolute" name="joint_iip_thumb">
      <parent link="thumb_pp"/>
      <child link="joint_iip_thumb_jointbody"/>
      <origin xyz="-2.5364699896779245e-16 5.2599154258198517e-17 -1.0558595790610728e-17" rpy="3.1415926535897927 1.5707963267948948 0.0"/>
      <axis xyz="0.0 -1.0 0.0"/>
      <limit lower="-0.3490658503988659" upper="2.0943951023931953" effort="100" velocity="100"/>
   </joint>
   <joint type="fixed" name="joint_iip_thumb_offset">
      <parent link="joint_iip_thumb_jointbody"/>
      <child link="thumb_ip"/>
      <origin xyz="-0.0 -0.0 -0.0" rpy="0.0 0.0 0.0"/>
   </joint>
   <link name="thumb_dp">
      <inertial>
         <origin xyz="0.0019263407363933048 1.4557758490367377e-05 0.013252605089620229" rpy="0.0005042469448421566 -0.01731928165759511 -0.007693848109361373"/>
         <mass value="0.01818889883021656"/>
         <inertia ixx="1.7342479877374563e-06" iyy="1.6928601517092007e-06" izz="6.72000990269703e-07" ixy="0" ixz="0" iyz="0"/>
      </inertial>
      <visual name="thumb_dp_mesh">
         <origin xyz="0.0019263407363933048 1.4557758490367377e-05 0.013252605089620229" rpy="0.0005042469448421566 -0.01731928165759511 -0.007693848109361373"/>
         <geometry>
            <mesh filename="assets/thumb_dp.stl"/>
         </geometry>
         <material name="white"/>
      </visual>
   </link>
   <link name="joint_dip_thumb_jointbody">
      <inertial>
         <origin xyz="0.0 0.0 0.0" rpy="0.0 0.0 0.0"/>
         <mass value="0.001"/>
         <inertia ixx="1e-09" iyy="1e-09" izz="1e-09" ixy="0" ixz="0" iyz="0"/>
      </inertial>
   </link>
   <joint type="revolute" name="joint_dip_thumb">
      <parent link="thumb_ip"/>
      <child link="joint_dip_thumb_jointbody"/>
      <origin xyz="0.0004999999999720094 -6.765421556309548e-16 0.03299999999999984" rpy="2.4424906541753483e-15 2.220446049250313e-15 1.4988010832439653e-15"/>
      <axis xyz="0.0 -1.0 0.0"/>
      <limit lower="-0.3490658503988659" upper="2.6179938779914944" effort="100" velocity="100"/>
   </joint>
   <joint type="fixed" name="joint_dip_thumb_offset">
      <parent link="joint_dip_thumb_jointbody"/>
      <child link="thumb_dp"/>
      <origin xyz="-0.0 -0.0 -0.0" rpy="0.0 0.0 0.0"/>
   </joint>
   <link name="index_mp">
      <inertial>
         <origin xyz="0.011324882177565752 -1.6941348925356174e-06 -5.315993119961997e-05" rpy="-0.190916891564884 -1.5652169479008922 -2.95084014845112"/>
         <mass value="0.006663688695825763"/>
         <inertia ixx="4.78042566224753e-07" iyy="4.443859855677583e-07" izz="2.7318510047914545e-07" ixy="0" ixz="0" iyz="0"/>
      </inertial>
      <visual name="index_mp_mesh">
         <origin xyz="0.011324882177565752 -1.6941348925356174e-06 -5.315993119961997e-05" rpy="-0.19091689156488423 -1.5652169479008922 -2.9508401484511197"/>
         <geometry>
            <mesh filename="assets/index_mp.stl"/>
         </geometry>
         <material name="white"/>
      </visual>
   </link>
   <link name="joint_abd_index_jointbody">
      <inertial>
         <origin xyz="0.0 0.0 0.0" rpy="0.0 0.0 0.0"/>
         <mass value="0.001"/>
         <inertia ixx="1e-09" iyy="1e-09" izz="1e-09" ixy="0" ixz="0" iyz="0"/>
      </inertial>
   </link>
   <joint type="revolute" name="joint_abd_index">
      <parent link="palm"/>
      <child link="joint_abd_index_jointbody"/>
      <origin xyz="-0.024091784930027955 0.0019042822195537508 0.025160679302659018" rpy="1.6066965884733262 1.1355216005349669 -0.053392057607510646"/>
      <axis xyz="8.326672684688674e-17 1.1102230246251565e-16 -1.0"/>
      <limit lower="-0.5235987755982988" upper="0.5235987755982988" effort="100" velocity="100"/>
   </joint>
   <joint type="fixed" name="joint_abd_index_offset">
      <parent link="joint_abd_index_jointbody"/>
      <child link="index_mp"/>
      <origin xyz="-0.01999999999999969 -1.222980050563649e-16 -2.6020852139652106e-18" rpy="0.0 0.0 0.0"/>
   </joint>
   <link name="index_pp">
      <inertial>
         <origin xyz="0.0014172694291716091 7.000386677568159e-06 0.01611561640468115" rpy="-0.0005874283652808861 0.015490564105012927 0.0010684470451014292"/>
         <mass value="0.01872825606734759"/>
         <inertia ixx="2.667159592664703e-06" iyy="2.5701720075821575e-06" izz="8.02985620206854e-07" ixy="0" ixz="0" iyz="0"/>
      </inertial>
      <visual name="index_pp_mesh">
         <origin xyz="0.0014172694291716091 7.000386677568159e-06 0.01611561640468115" rpy="-0.0005874283652808861 0.015490564105012927 0.0010684470451014292"/>
         <geometry>
            <mesh filename="assets/index_pp.stl"/>
         </geometry>
         <material name="white"/>
      </visual>
   </link>
   <link name="joint_pip_index_jointbody">
      <inertial>
         <origin xyz="0.0 0.0 0.0" rpy="0.0 0.0 0.0"/>
         <mass value="0.001"/>
         <inertia ixx="1e-09" iyy="1e-09" izz="1e-09" ixy="0" ixz="0" iyz="0"/>
      </inertial>
   </link>
   <joint type="revolute" name="joint_pip_index">
      <parent link="index_mp"/>
      <child link="joint_pip_index_jointbody"/>
      <origin xyz="9.072004747067653e-17 -2.0636548322369215e-18 9.00862880334811e-18" rpy="7.850462293418878e-17 -1.5707963267948963 0.0"/>
      <axis xyz="2.7755575615628914e-16 -1.0000000000000013 3.3306690738754696e-16"/>
      <limit lower="-0.3490658503988659" upper="1.9198621771937625" effort="100" velocity="100"/>
   </joint>
   <joint type="fixed" name="joint_pip_index_offset">
      <parent link="joint_pip_index_jointbody"/>
      <child link="index_pp"/>
      <origin xyz="-7.643495558336816e-18 -2.0383250328514768e-17 9.34495075168305e-18" rpy="0.0 0.0 0.0"/>
   </joint>
   <link name="index_ip">
      <inertial>
         <origin xyz="0.0004395758025904904 2.294210842752089e-05 0.017234999921076924" rpy="-0.0002952414540531474 -0.13694120498566353 0.004582776782163111"/>
         <mass value="0.018229214728618118"/>
         <inertia ixx="2.7483316705449915e-06" iyy="2.7260398150926247e-06" izz="5.982307965118894e-07" ixy="0" ixz="0" iyz="0"/>
      </inertial>
      <visual name="index_ip_mesh">
         <origin xyz="0.0004395758025904904 2.294210842752089e-05 0.017234999921076924" rpy="-0.0002952414540531474 -0.13694120498566353 0.004582776782163111"/>
         <geometry>
            <mesh filename="assets/index_ip.stl"/>
         </geometry>
         <material name="white"/>
      </visual>
   </link>
   <link name="joint_iip_index_jointbody">
      <inertial>
         <origin xyz="0.0 0.0 0.0" rpy="0.0 0.0 0.0"/>
         <mass value="0.001"/>
         <inertia ixx="1e-09" iyy="1e-09" izz="1e-09" ixy="0" ixz="0" iyz="0"/>
      </inertial>
   </link>
   <joint type="revolute" name="joint_iip_index">
      <parent link="index_pp"/>
      <child link="joint_iip_index_jointbody"/>
      <origin xyz="0.0004999999999839698 5.698990924330967e-17 0.03799999999999997" rpy="0.0 0.0 -1.1102230246251565e-16"/>
      <axis xyz="1.1102230246251565e-16 -0.9999999999999994 3.191891195797325e-16"/>
      <limit lower="-0.3490658503988659" upper="2.2689280275926285" effort="100" velocity="100"/>
   </joint>
   <joint type="fixed" name="joint_iip_index_offset">
      <parent link="joint_iip_index_jointbody"/>
      <child link="index_ip"/>
      <origin xyz="5.782630065573341e-18 -2.2295439723773536e-17 -2.0152132784981046e-17" rpy="0.0 0.0 0.0"/>
   </joint>
   <link name="middle_mp">
      <inertial>
         <origin xyz="0.011324882177565752 -1.6941348925356174e-06 -5.315993119961997e-05" rpy="-0.190916891564884 -1.5652169479008922 -2.95084014845112"/>
         <mass value="0.006663688695825763"/>
         <inertia ixx="4.78042566224753e-07" iyy="4.443859855677583e-07" izz="2.7318510047914545e-07" ixy="0" ixz="0" iyz="0"/>
      </inertial>
      <visual name="middle_mp_mesh">
         <origin xyz="0.011324882177565752 -1.6941348925356174e-06 -5.315993119961997e-05" rpy="-0.19091689156488423 -1.5652169479008922 -2.9508401484511197"/>
         <geometry>
            <mesh filename="assets/middle_mp.stl"/>
         </geometry>
         <material name="white"/>
      </visual>
   </link>
   <link name="joint_abd_middle_jointbody">
      <inertial>
         <origin xyz="0.0 0.0 0.0" rpy="0.0 0.0 0.0"/>
         <mass value="0.001"/>
         <inertia ixx="1e-09" iyy="1e-09" izz="1e-09" ixy="0" ixz="0" iyz="0"/>
      </inertial>
   </link>
   <joint type="revolute" name="joint_abd_middle">
      <parent link="palm"/>
      <child link="joint_abd_middle_jointbody"/>
      <origin xyz="0.02151626244325176 0.0015399660708893441 0.020821937215657737" rpy="-1.5359724334240132 1.3083608795701238 -3.0544118070011477"/>
      <axis xyz="5.828670879282072e-16 -2.220446049250313e-16 -0.9999999999999996"/>
      <limit lower="-0.5235987755982988" upper="0.5235987755982988" effort="100" velocity="100"/>
   </joint>
   <joint type="fixed" name="joint_abd_middle_offset">
      <parent link="joint_abd_middle_jointbody"/>
      <child link="middle_mp"/>
      <origin xyz="-0.019999999999999712 8.239936510889834e-17 -6.071532165918825e-18" rpy="0.0 0.0 0.0"/>
   </joint>
   <link name="middle_pp">
      <inertial>
         <origin xyz="0.0015215641155183913 3.409155126104343e-06 0.019988197676665105" rpy="-0.0008675700761155622 0.013815007172908844 0.001849376719566181"/>
         <mass value="0.023556963904505242"/>
         <inertia ixx="4.4203229364973464e-06" iyy="4.276694367220302e-06" izz="1.0089823927588865e-06" ixy="0" ixz="0" iyz="0"/>
      </inertial>
      <visual name="middle_pp_mesh">
         <origin xyz="0.0015215641155183913 3.409155126104343e-06 0.019988197676665105" rpy="-0.000867570076115562 0.013815007172908844 0.0018493767195661807"/>
         <geometry>
            <mesh filename="assets/middle_pp.stl"/>
         </geometry>
         <material name="white"/>
      </visual>
   </link>
   <link name="joint_pip_middle_jointbody">
      <inertial>
         <origin xyz="0.0 0.0 0.0" rpy="0.0 0.0 0.0"/>
         <mass value="0.001"/>
         <inertia ixx="1e-09" iyy="1e-09" izz="1e-09" ixy="0" ixz="0" iyz="0"/>
      </inertial>
   </link>
   <joint type="revolute" name="joint_pip_middle">
      <parent link="middle_mp"/>
      <child link="joint_pip_middle_jointbody"/>
      <origin xyz="-2.739291165494201e-16 5.658164857459344e-17 -8.813617833534736e-18" rpy="0.0 -1.5707963267948963 0.0"/>
      <axis xyz="-3.3306690738754696e-16 -1.0000000000000007 8.743006318923108e-16"/>
      <limit lower="-0.3490658503988659" upper="1.9198621771937625" effort="100" velocity="100"/>
   </joint>
   <joint type="fixed" name="joint_pip_middle_offset">
      <parent link="joint_pip_middle_jointbody"/>
      <child link="middle_pp"/>
      <origin xyz="6.29584589194853e-18 -1.1842556896340075e-17 -1.1819659490533676e-16" rpy="0.0 0.0 0.0"/>
   </joint>
   <link name="middle_ip">
      <inertial>
         <origin xyz="0.0004395758025904904 2.294210842752089e-05 0.017234999921076924" rpy="-0.0002952414540531474 -0.13694120498566353 0.004582776782163111"/>
         <mass value="0.018229214728618118"/>
         <inertia ixx="2.7483316705449915e-06" iyy="2.7260398150926247e-06" izz="5.982307965118894e-07" ixy="0" ixz="0" iyz="0"/>
      </inertial>
      <visual name="middle_ip_mesh">
         <origin xyz="0.0004395758025904904 2.294210842752089e-05 0.017234999921076924" rpy="-0.0002952414540531474 -0.13694120498566353 0.004582776782163111"/>
         <geometry>
            <mesh filename="assets/middle_ip.stl"/>
         </geometry>
         <material name="white"/>
      </visual>
   </link>
   <link name="joint_iip_middle_jointbody">
      <inertial>
         <origin xyz="0.0 0.0 0.0" rpy="0.0 0.0 0.0"/>
         <mass value="0.001"/>
         <inertia ixx="1e-09" iyy="1e-09" izz="1e-09" ixy="0" ixz="0" iyz="0"/>
      </inertial>
   </link>
   <joint type="revolute" name="joint_iip_middle">
      <parent link="middle_pp"/>
      <child link="joint_iip_middle_jointbody"/>
      <origin xyz="0.0004999999999727302 2.6466541427033214e-17 0.045999999999999916" rpy="-6.938893903907228e-17 0.0 -1.1102230246251565e-16"/>
      <axis xyz="-2.220446049250313e-16 -1.0000000000000004 9.298117831235686e-16"/>
      <limit lower="-0.3490658503988659" upper="2.2689280275926285" effort="100" velocity="100"/>
   </joint>
   <joint type="fixed" name="joint_iip_middle_offset">
      <parent link="joint_iip_middle_jointbody"/>
      <child link="middle_ip"/>
      <origin xyz="1.95471717076309e-17 -5.465579791165633e-17 -1.4856164371462412e-17" rpy="0.0 0.0 0.0"/>
   </joint>
   <link name="ring_mp">
      <inertial>
         <origin xyz="0.011324882177565752 -1.6941348925356174e-06 -5.315993119961997e-05" rpy="-0.190916891564884 -1.5652169479008922 -2.95084014845112"/>
         <mass value="0.006663688695825763"/>
         <inertia ixx="4.78042566224753e-07" iyy="4.443859855677583e-07" izz="2.7318510047914545e-07" ixy="0" ixz="0" iyz="0"/>
      </inertial>
      <visual name="ring_mp_mesh">
         <origin xyz="0.011324882177565752 -1.6941348925356174e-06 -5.315993119961997e-05" rpy="-0.19091689156488423 -1.5652169479008922 -2.9508401484511197"/>
         <geometry>
            <mesh filename="assets/ring_mp.stl"/>
         </geometry>
         <material name="white"/>
      </visual>
   </link>
   <link name="joint_abd_ring_jointbody">
      <inertial>
         <origin xyz="0.0 0.0 0.0" rpy="0.0 0.0 0.0"/>
         <mass value="0.001"/>
         <inertia ixx="1e-09" iyy="1e-09" izz="1e-09" ixy="0" ixz="0" iyz="0"/>
      </inertial>
   </link>
   <joint type="revolute" name="joint_abd_ring">
      <parent link="palm"/>
      <child link="joint_abd_ring_jointbody"/>
      <origin xyz="-3.178399083063177e-17 1.2056328158038776e-17 0.02999999999999983" rpy="1.570796326794897 1.5707963267948961 0.0"/>
      <axis xyz="4.440892098500626e-16 -4.440892098500626e-16 -0.9999999999999987"/>
      <limit lower="-0.5235987755982988" upper="0.5235987755982988" effort="100" velocity="100"/>
   </joint>
   <joint type="fixed" name="joint_abd_ring_offset">
      <parent link="joint_abd_ring_jointbody"/>
      <child link="ring_mp"/>
      <origin xyz="-0.019999999999999882 4.336808689942018e-18 -9.540979117872439e-18" rpy="0.0 0.0 0.0"/>
   </joint>
   <link name="ring_pp">
      <inertial>
         <origin xyz="0.0015215641155183913 3.409155126104343e-06 0.019988197676665105" rpy="-0.0008675700761155622 0.013815007172908844 0.001849376719566181"/>
         <mass value="0.023556963904505242"/>
         <inertia ixx="4.4203229364973464e-06" iyy="4.276694367220302e-06" izz="1.0089823927588865e-06" ixy="0" ixz="0" iyz="0"/>
      </inertial>
      <visual name="ring_pp_mesh">
         <origin xyz="0.0015215641155183913 3.409155126104343e-06 0.019988197676665105" rpy="-0.000867570076115562 0.013815007172908844 0.0018493767195661807"/>
         <geometry>
            <mesh filename="assets/ring_pp.stl"/>
         </geometry>
         <material name="white"/>
      </visual>
   </link>
   <link name="joint_pip_ring_jointbody">
      <inertial>
         <origin xyz="0.0 0.0 0.0" rpy="0.0 0.0 0.0"/>
         <mass value="0.001"/>
         <inertia ixx="1e-09" iyy="1e-09" izz="1e-09" ixy="0" ixz="0" iyz="0"/>
      </inertial>
   </link>
   <joint type="revolute" name="joint_pip_ring">
      <parent link="ring_mp"/>
      <child link="joint_pip_ring_jointbody"/>
      <origin xyz="-4.260755233192973e-34 5.7777898331617076e-34 1.301042606982604e-18" rpy="0.0 -1.5707963267948963 0.0"/>
      <axis xyz="6.106226635438361e-16 -0.9999999999999997 -1.035742568734697e-16"/>
      <limit lower="-0.3490658503988659" upper="1.9198621771937625" effort="100" velocity="100"/>
   </joint>
   <joint type="fixed" name="joint_pip_ring_offset">
      <parent link="joint_pip_ring_jointbody"/>
      <child link="ring_pp"/>
      <origin xyz="-1.301042606982604e-18 -5.7777898331617076e-34 -7.149650149773824e-34" rpy="0.0 0.0 0.0"/>
   </joint>
   <link name="ring_ip">
      <inertial>
         <origin xyz="0.0004395758025904904 2.294210842752089e-05 0.017234999921076924" rpy="-0.0002952414540531474 -0.13694120498566353 0.004582776782163111"/>
         <mass value="0.018229214728618118"/>
         <inertia ixx="2.7483316705449915e-06" iyy="2.7260398150926247e-06" izz="5.982307965118894e-07" ixy="0" ixz="0" iyz="0"/>
      </inertial>
      <visual name="ring_ip_mesh">
         <origin xyz="0.0004395758025904904 2.294210842752089e-05 0.017234999921076924" rpy="-0.0002952414540531474 -0.13694120498566353 0.004582776782163111"/>
         <geometry>
            <mesh filename="assets/ring_ip.stl"/>
         </geometry>
         <material name="white"/>
      </visual>
   </link>
   <link name="joint_iip_ring_jointbody">
      <inertial>
         <origin xyz="0.0 0.0 0.0" rpy="0.0 0.0 0.0"/>
         <mass value="0.001"/>
         <inertia ixx="1e-09" iyy="1e-09" izz="1e-09" ixy="0" ixz="0" iyz="0"/>
      </inertial>
   </link>
   <joint type="revolute" name="joint_iip_ring">
      <parent link="ring_pp"/>
      <child link="joint_iip_ring_jointbody"/>
      <origin xyz="0.0004999999999727385 -8.944667923005355e-18 0.04600000000000013" rpy="0.0 0.0 0.0"/>
      <axis xyz="6.106226635438361e-16 -0.9999999999999997 -1.035742568734697e-16"/>
      <limit lower="-0.3490658503988659" upper="2.2689280275926285" effort="100" velocity="100"/>
   </joint>
   <joint type="fixed" name="joint_iip_ring_offset">
      <parent link="joint_iip_ring_jointbody"/>
      <child link="ring_ip"/>
      <origin xyz="2.1792463666958658e-17 6.938893903907171e-18 -8.326672684688664e-17" rpy="0.0 0.0 0.0"/>
   </joint>
   <link name="pinky_mp">
      <inertial>
         <origin xyz="0.011324882177565752 -1.6941348925356174e-06 -5.315993119961997e-05" rpy="-0.190916891564884 -1.5652169479008922 -2.95084014845112"/>
         <mass value="0.006663688695825763"/>
         <inertia ixx="4.78042566224753e-07" iyy="4.443859855677583e-07" izz="2.7318510047914545e-07" ixy="0" ixz="0" iyz="0"/>
      </inertial>
      <visual name="pinky_mp_mesh">
         <origin xyz="0.011324882177565752 -1.6941348925356174e-06 -5.315993119961997e-05" rpy="-0.19091689156488423 -1.5652169479008922 -2.9508401484511197"/>
         <geometry>
            <mesh filename="assets/pinky_mp.stl"/>
         </geometry>
         <material name="white"/>
      </visual>
   </link>
   <link name="joint_abd_pinky_jointbody">
      <inertial>
         <origin xyz="0.0 0.0 0.0" rpy="0.0 0.0 0.0"/>
         <mass value="0.001"/>
         <inertia ixx="1e-09" iyy="1e-09" izz="1e-09" ixy="0" ixz="0" iyz="0"/>
      </inertial>
   </link>
   <joint type="revolute" name="joint_abd_pinky">
      <parent link="palm"/>
      <child link="joint_abd_pinky_jointbody"/>
      <origin xyz="0.042587682827929796 0.004991925321003609 0.007247738795820422" rpy="-1.4969430651841686 0.8614853700810632 -2.8837300965971076"/>
      <axis xyz="-4.996003610813204e-16 -2.7755575615628914e-16 -0.9999999999999987"/>
      <limit lower="-0.5235987755982988" upper="0.5235987755982988" effort="100" velocity="100"/>
   </joint>
   <joint type="fixed" name="joint_abd_pinky_offset">
      <parent link="joint_abd_pinky_jointbody"/>
      <child link="pinky_mp"/>
      <origin xyz="-0.02000000000000019 2.47198095326695e-17 6.158268339717665e-17" rpy="0.0 0.0 0.0"/>
   </joint>
   <link name="pinky_pp">
      <inertial>
         <origin xyz="0.0014193666210186085 8.673552400660678e-06 0.013611608297713454" rpy="-0.0006651622688937844 0.02470989391442102 0.0013108316876743052"/>
         <mass value="0.015525372290662061"/>
         <inertia ixx="1.849733004237475e-06" iyy="1.7750616046334623e-06" izz="6.56720600070246e-07" ixy="0" ixz="0" iyz="0"/>
      </inertial>
      <visual name="pinky_pp_mesh">
         <origin xyz="0.0014193666210186085 8.673552400660678e-06 0.013611608297713454" rpy="-0.0006651622688937844 0.02470989391442102 0.0013108316876743052"/>
         <geometry>
            <mesh filename="assets/pinky_pp.stl"/>
         </geometry>
         <material name="white"/>
      </visual>
   </link>
   <link name="joint_pip_pinky_jointbody">
      <inertial>
         <origin xyz="0.0 0.0 0.0" rpy="0.0 0.0 0.0"/>
         <mass value="0.001"/>
         <inertia ixx="1e-09" iyy="1e-09" izz="1e-09" ixy="0" ixz="0" iyz="0"/>
      </inertial>
   </link>
   <joint type="revolute" name="joint_pip_pinky">
      <parent link="pinky_mp"/>
      <child link="joint_pip_pinky_jointbody"/>
      <origin xyz="9.859570060903676e-17 -2.9392458236684397e-17 4.429782895373408e-18" rpy="3.1401849173675513e-16 -1.5707963267948961 0.0"/>
      <axis xyz="1.6653345369377348e-16 -0.9999999999999994 -1.1102230246251565e-16"/>
      <limit lower="-0.3490658503988659" upper="1.9198621771937625" effort="100" velocity="100"/>
   </joint>
   <joint type="fixed" name="joint_pip_pinky_offset">
      <parent link="joint_pip_pinky_jointbody"/>
      <child link="pinky_pp"/>
      <origin xyz="7.273901839467707e-19 3.5634470632665727e-17 -4.269871636738011e-17" rpy="0.0 0.0 0.0"/>
   </joint>
   <link name="pinky_ip">
      <inertial>
         <origin xyz="0.0004395758025904904 2.294210842752089e-05 0.017234999921076924" rpy="-0.0002952414540531474 -0.13694120498566353 0.004582776782163111"/>
         <mass value="0.018229214728618118"/>
         <inertia ixx="2.7483316705449915e-06" iyy="2.7260398150926247e-06" izz="5.982307965118894e-07" ixy="0" ixz="0" iyz="0"/>
      </inertial>
      <visual name="pinky_ip_mesh">
         <origin xyz="0.0004395758025904904 2.294210842752089e-05 0.017234999921076924" rpy="-0.0002952414540531474 -0.13694120498566353 0.004582776782163111"/>
         <geometry>
            <mesh filename="assets/pinky_ip.stl"/>
         </geometry>
         <material name="white"/>
      </visual>
   </link>
   <link name="joint_iip_pinky_jointbody">
      <inertial>
         <origin xyz="0.0 0.0 0.0" rpy="0.0 0.0 0.0"/>
         <mass value="0.001"/>
         <inertia ixx="1e-09" iyy="1e-09" izz="1e-09" ixy="0" ixz="0" iyz="0"/>
      </inertial>
   </link>
   <joint type="revolute" name="joint_iip_pinky">
      <parent link="pinky_pp"/>
      <child link="joint_iip_pinky_jointbody"/>
      <origin xyz="0.0004999999999844794 -4.138564265705415e-18 0.03300000000000015" rpy="-1.665334536937734e-16 -6.661338147750939e-16 1.1102230246251563e-16"/>
      <axis xyz="3.885780586188048e-16 -0.9999999999999989 4.718447854656915e-16"/>
      <limit lower="-0.3490658503988659" upper="2.2689280275926285" effort="100" velocity="100"/>
   </joint>
   <joint type="fixed" name="joint_iip_pinky_offset">
      <parent link="joint_iip_pinky_jointbody"/>
      <child link="pinky_ip"/>
      <origin xyz="1.8619324129843582e-17 3.362886335731112e-17 6.41845325535561e-17" rpy="0.0 0.0 0.0"/>
   </joint>
   <material name="white">
      <color rgba="1 1 1 1"/>
   </material>
</robot>
